Workbook

Sheet March 2022
A8: Smartcode Technologies Limited | E8: PAYSLIP
A9: The Life Ministry House, Rose Avenue
A10: P.O Box 286 - 00517 Nairobi
A11: Nairobi, Kenya.
A13: EMPLOYEE | C13: PAY DATE | D13: PAY TYPE | E13: PERIOD
A14: Gideon Mwangi Kabaru | C14: =Sheet2!A10 -> 44651 | D14: Monthly | E14: =Sheet2!D10 -> 44621
A15: P.O Box 286-00517, | B15: [42] | C15: PAYROLL # | D15: ID NUMBER | E15: TAX CODE
A16: Nairobi Kenya | C16: TED0003 | D16: 24676384 | E16: A004520490R
A17: Phone: +254 725 800 277
A18: Email: gideon@smartcode.co.ke | C18: Payment Method: | D18: EFT
A20: EARNINGS | B20: HOURS | C20: RATE | D20: CURRENT | E20: YTD
A21: Basic Pay | B21: =Sheet2!E9 -> 160 | C21: =Sheet2!F8 -> 937.5 | D21: =C21*B21 -> 150000 | E21: =D21 -> 150000
A22: Overtime Pay | B22: 74.335008 | C22: =Sheet2!I8 -> 937.5 | D22: =B22*C22 -> 69689.07 | E22: =D22 -> 69689.07
A23: Holiday Pay | B23: 0 | C23: 0 | D23: 0 | E23: =C23*D23 -> 0
A24: Vacation Pay | B24: 0 | C24: 0 | D24: 0 | E24: =C24*D24 -> 0
A25: Other Hourly Pay | B25: 0 | C25: 0 | D25: 0 | E25: =C25*D25 -> 0
A26: Basic Pay | B26: 0 | C26: 0 | D26: 0 | E26: =C26*D26 -> 0
A27: Commission and Bonus | B27: 0 | C27: 0 | D27: 0 | E27: =C27*D27 -> 0
A28: Sick Pay | B28: 0 | C28: 0 | D28: 0 | E28: =C28*D28 -> 0
A29: Expenses | B29: 0 | C29: 0 | D29: 0 | E29: =C29*D29 -> 0
A30: 0
A31: 0
A32: 0
A33: 0
C34: GROSS PAY | D34: =SUM(D21:D33) -> 219689.07 | E34: =SUM(E21:E33) -> 219689.07
A36: DEDUCTIONS | D36: CURRENT | E36: YTD
A37: PAYE Tax | D37: 57975.07 | E37: =D37 -> 57975.07
A38: N.H.I.F | D38: 1700 | E38: =D38 -> 1700
A39: HELB | D39: 0 | E39: =D39 -> 0
A40: Pension | D40: 200 | E40: =D40 -> 200
A41: Union Fees | D41: 0 | E41: =D41 -> 0
A42: 0 | E42: 0
A43: 0 | E43: 0
A44: 0 | E44: 0
A45: 0 | E45: 0
A46: 0 | E46: 0
C47: TOTAL DEDUCTIONS | D47: =SUM(D37:D46) -> 59875.07 | E47: =SUM(E37:E46) -> 59875.07
C49: NET PAY | D49: =D34-D47 -> 159814 | E49: =E34-E47 -> 159814
A51: If you have any questions about this payslip, please contact:
A52: [Enock Ngeny, +254 722 608 131, enock@engkconsulting.co.ke]
...

Sheet Feb 2022
A8: Smartcode Technologies Limited | E8: PAYSLIP
A9: The Life Ministry House, Rose Avenue
A10: P.O Box 286 - 00517 Nairobi
A11: Nairobi, Kenya.
A13: EMPLOYEE | C13: PAY DATE | D13: PAY TYPE | E13: PERIOD
A14: Gideon Mwangi Kabaru | C14: =Sheet2!A9 -> 44620 | D14: Monthly | E14: =Sheet2!D9 -> 44593
A15: P.O Box 286-00517, | B15: [42] | C15: PAYROLL # | D15: ID NUMBER | E15: TAX CODE
A16: Nairobi Kenya | C16: TED0003 | D16: 24676384 | E16: A004520490R
A17: Phone: +254 725 800 277
A18: Email: gideon@smartcode.co.ke | C18: Payment Method: | D18: EFT
A20: EARNINGS | B20: HOURS | C20: RATE | D20: CURRENT | E20: YTD
A21: Basic Pay | B21: =Sheet2!E9 -> 160 | C21: =Sheet2!F8 -> 937.5 | D21: =C21*B21 -> 150000 | E21: =D21 -> 150000
A22: Overtime Pay | B22: 74.335008 | C22: =Sheet2!I8 -> 937.5 | D22: =B22*C22 -> 69689.07 | E22: =D22 -> 69689.07
A23: Holiday Pay | B23: 0 | C23: 0 | D23: 0 | E23: =C23*D23 -> 0
A24: Vacation Pay | B24: 0 | C24: 0 | D24: 0 | E24: =C24*D24 -> 0
A25: Other Hourly Pay | B25: 0 | C25: 0 | D25: 0 | E25: =C25*D25 -> 0
A26: Basic Pay | B26: 0 | C26: 0 | D26: 0 | E26: =C26*D26 -> 0
A27: Commission and Bonus | B27: 0 | C27: 0 | D27: 0 | E27: =C27*D27 -> 0
A28: Sick Pay | B28: 0 | C28: 0 | D28: 0 | E28: =C28*D28 -> 0
A29: Expenses | B29: 0 | C29: 0 | D29: 0 | E29: =C29*D29 -> 0
A30: 0
A31: 0
A32: 0
A33: 0
C34: GROSS PAY | D34: =SUM(D21:D33) -> 219689.07 | E34: =SUM(E21:E33) -> 219689.07
A36: DEDUCTIONS | D36: CURRENT | E36: YTD
A37: PAYE Tax | D37: 57975.07 | E37: =D37 -> 57975.07
A38: N.H.I.F | D38: 1700 | E38: =D38 -> 1700
A39: HELB | D39: 0 | E39: =D39 -> 0
A40: Pension | D40: 200 | E40: =D40 -> 200
A41: Union Fees | D41: 0 | E41: =D41 -> 0
A42: 0 | E42: 0
A43: 0 | E43: 0
A44: 0 | E44: 0
A45: 0 | E45: 0
A46: 0 | E46: 0
C47: TOTAL DEDUCTIONS | D47: =SUM(D37:D46) -> 59875.07 | E47: =SUM(E37:E46) -> 59875.07
C49: NET PAY | D49: =D34-D47 -> 159814 | E49: =E34-E47 -> 159814
A51: If you have any questions about this payslip, please contact:
A52: [Enock Ngeny, +254 722 608 131, enock@engkconsulting.co.ke]
...

Sheet Jan 2022
A8: Smartcode Technologies Limited | E8: PAYSLIP
A9: The Life Ministry House, Rose Avenue
A10: P.O Box 286 - 00517 Nairobi
A11: Nairobi, Kenya.
A13: EMPLOYEE | C13: PAY DATE | D13: PAY TYPE | E13: PERIOD
A14: Gideon Mwangi Kabaru | C14: =Sheet2!A8 -> 44592 | D14: Monthly | E14: 44562
A15: P.O Box 286-00517, | B15: [42] | C15: PAYROLL # | D15: ID NUMBER | E15: TAX CODE
A16: Nairobi Kenya | C16: TED0003 | D16: 24676384 | E16: A004520490R
A17: Phone: +254 725 800 277
A18: Email: gideon@smartcode.co.ke | C18: Payment Method: | D18: EFT
A20: EARNINGS | B20: HOURS | C20: RATE | D20: CURRENT | E20: YTD
A21: Basic Pay | B21: =Sheet2!E8 -> 160 | C21: =Sheet2!F8 -> 937.5 | D21: =C21*B21 -> 150000 | E21: =D21 -> 150000
A22: Overtime Pay | B22: 74.335008 | C22: =Sheet2!I8 -> 937.5 | D22: =B22*C22 -> 69689.07 | E22: =D22 -> 69689.07
A23: Holiday Pay | B23: 0 | C23: 0 | D23: 0 | E23: =C23*D23 -> 0
A24: Vacation Pay | B24: 0 | C24: 0 | D24: 0 | E24: =C24*D24 -> 0
A25: Other Hourly Pay | B25: 0 | C25: 0 | D25: 0 | E25: =C25*D25 -> 0
A26: Basic Pay | B26: 0 | C26: 0 | D26: 0 | E26: =C26*D26 -> 0
A27: Commission and Bonus | B27: 0 | C27: 0 | D27: 0 | E27: =C27*D27 -> 0
A28: Sick Pay | B28: 0 | C28: 0 | D28: 0 | E28: =C28*D28 -> 0
A29: Expenses | B29: 0 | C29: 0 | D29: 0 | E29: =C29*D29 -> 0
A30: 0
A31: 0
A32: 0
A33: 0
C34: GROSS PAY | D34: =SUM(D21:D33) -> 219689.07 | E34: =SUM(E21:E33) -> 219689.07
A36: DEDUCTIONS | D36: CURRENT | E36: YTD
A37: PAYE Tax | D37: 57975.07 | E37: =D37 -> 57975.07
A38: N.H.I.F | D38: 1700 | E38: =D38 -> 1700
A39: HELB | D39: 0 | E39: =D39 -> 0
A40: Pension | D40: 200 | E40: =D40 -> 200
A41: Union Fees | D41: 0 | E41: =D41 -> 0
A42: 0 | E42: 0
A43: 0 | E43: 0
A44: 0 | E44: 0
A45: 0 | E45: 0
A46: 0 | E46: 0
C47: TOTAL DEDUCTIONS | D47: =SUM(D37:D46) -> 59875.07 | E47: =SUM(E37:E46) -> 59875.07
C49: NET PAY | D49: =D34-D47 -> 159814 | E49: =E34-E47 -> 159814
A51: If you have any questions about this payslip, please contact:
A52: [Enock Ngeny, +254 722 608 131, enock@engkconsulting.co.ke]
...

Sheet Dec 2021
A8: Smartcode Technologies Limited | E8: PAYSLIP
A9: The Life Ministry House, Rose Avenue
A10: P.O Box 286 - 00517 Nairobi
A11: Nairobi, Kenya.
A13: EMPLOYEE | C13: PAY DATE | D13: PAY TYPE | E13: PERIOD
A14: Gideon Mwangi Kabaru | C14: =Sheet2!A7 -> 44561 | D14: Monthly | E14: 44531
A15: P.O Box 286-00517, | B15: [42] | C15: PAYROLL # | D15: ID NUMBER | E15: TAX CODE
A16: Nairobi Kenya | C16: TED0003 | D16: 24676384 | E16: A004520490R
A17: Phone: +254 725 800 277
A18: Email: gideon@smartcode.co.ke | C18: Payment Method: | D18: EFT
A20: EARNINGS | B20: HOURS | C20: RATE | D20: CURRENT | E20: YTD
A21: Basic Pay | B21: =Sheet2!E7 -> 160 | C21: =Sheet2!F7 -> 937.5 | D21: =C21*B21 -> 150000 | E21: =D21 -> 150000
A22: Overtime Pay | B22: 84.5232 | C22: =Sheet2!I7 -> 937.5 | D22: =B22*C22 -> 79240.5 | E22: =D22 -> 79240.5
A23: Holiday Pay | B23: 0 | C23: 0 | D23: =B23*C23 -> 0 | E23: =D23 -> 0
A24: Vacation Pay | B24: 0 | C24: 0 | D24: =B24*C24 -> 0 | E24: =D24 -> 0
A25: Other Hourly Pay | B25: 0 | C25: 0 | D25: =B25*C25 -> 0 | E25: =D25 -> 0
A26: Other Basic Pay | B26: 0 | C26: 0 | D26: =B26*C26 -> 0 | E26: =D26 -> 0
A27: Commission and Bonus | B27: 0 | C27: 0 | D27: =B27*C27 -> 0 | E27: =D27 -> 0
A28: Sick Pay | B28: 0 | C28: 0 | D28: =B28*C28 -> 0 | E28: =D28 -> 0
A29: Expenses | B29: 0 | C29: 0 | D29: =B29*C29 -> 0 | E29: =D29 -> 0
A30: 0 | E30: 0
A31: 0 | E31: 0
A32: 0 | E32: 0
A33: 0 | E33: 0
C34: GROSS PAY | D34: =SUM(D21:D33) -> 229240.5 | E34: =SUM(E21:E33) -> 229240.5
A36: DEDUCTIONS | D36: CURRENT | E36: YTD
A37: PAYE Tax | D37: 60840.5 | E37: =D37 -> 60840.5
A38: N.H.I.F | D38: 1700 | E38: =D38 -> 1700
A39: HELB | D39: 0 | E39: =D39 -> 0
A40: Pension | D40: 200 | E40: =D40 -> 200
A41: Union Fees | D41: 0 | E41: =D41 -> 0
A42: 0 | E42: =D42
A43: 0 | E43: =D43
A44: 0 | E44: =D44
A45: 0 | E45: =D45
A46: 0 | E46: =D46
C47: TOTAL DEDUCTIONS | D47: =SUM(D37:D46) -> 62740.5 | E47: =SUM(E37:E46) -> 62740.5
C49: NET PAY | D49: =D34-D47 -> 166500 | E49: =E34-E47 -> 166500
A51: If you have any questions about this payslip, please contact:
A52: [Enock Ngeny, +254 722 608 131, enock@engkconsulting.co.ke]
...

Sheet Nov 2021
A8: Smartcode Technologies Limited | E8: PAYSLIP
A9: The Life Ministry House, Rose Avenue
A10: P.O Box 286 - 00517 Nairobi
A11: Nairobi, Kenya.
A13: EMPLOYEE | C13: PAY DATE | D13: PAY TYPE | E13: PERIOD
A14: Gideon Mwangi Kabaru | C14: =Sheet2!A6 -> 44530 | D14: Monthly | E14: 44501
A15: P.O Box 286-00517, | B15: [42] | C15: PAYROLL # | D15: ID NUMBER | E15: TAX CODE
A16: Nairobi Kenya | C16: TED0003 | D16: 24676384 | E16: A004520490R
A17: Phone: +254 725 800 277
A18: Email: gideon@smartcode.co.ke | C18: Payment Method: | D18: EFT
A20: EARNINGS | B20: HOURS | C20: RATE | D20: CURRENT | E20: YTD
A21: Basic Pay | B21: 160 | C21: 937.5 | D21: 150000 | E21: 150000
A22: Overtime Pay | B22: =Sheet2!H6 -> 74.618432 | C22: 937.5 | D22: 79968.75 | E22: 79968.75
A23: Holiday Pay | B23: 0 | C23: 0 | D23: 0 | E23: 0
A24: Vacation Pay | B24: 0 | C24: 0 | D24: 0 | E24: 0
A25: Other Hourly Pay | B25: 0 | C25: 0 | D25: 0 | E25: 0
A26: Basic Pay | B26: 0 | C26: 0 | D26: 0 | E26: 0
A27: Commission and Bonus | B27: 0 | C27: 0 | D27: 0 | E27: 0
A28: Sick Pay | B28: 0 | C28: 0 | D28: 0 | E28: 0
A29: Expenses | B29: 0 | C29: 0 | D29: 0 | E29: 0
A30: 0 | E30: 0
A31: 0 | E31: 0
A32: 0 | E32: 0
A33: 0 | E33: 0
C34: GROSS PAY | D34: =SUM(D21:D33) -> 229968.75 | E34: =SUM(E21:E33) -> 229968.75
A36: DEDUCTIONS | D36: CURRENT | E36: YTD
A37: PAYE Tax | D37: 61054.78 | E37: 61054.78
A38: N.H.I.F | D38: 1700 | E38: 1700
A39: HELB | D39: 0 | E39: 0
A40: Pension | D40: 200 | E40: 200
A41: Union Fees | D41: 0 | E41: 0
A42: 0 | E42: 0
A43: 0 | E43: 0
A44: 0 | E44: 0
A45: 0 | E45: 0
A46: 0 | E46: 0
C47: TOTAL DEDUCTIONS | D47: =SUM(D37:D46) -> 62954.78 | E47: =SUM(E37:E46) -> 62954.78
C49: NET PAY | D49: =D34-D47 -> 167013.97 | E49: =E34-E47 -> 167013.97
A51: If you have any questions about this payslip, please contact:
A52: [Enock Ngeny, +254 722 608 131, enock@engkconsulting.co.ke]
...

Sheet Sheet2
A1: Payslip Year-to-Date Calculations | AM1: =HYPERLINK("https://www.vertex42.com/","by Vertex42.com") -> by Vertex42.com
D2: Employee: | E2: ='March 2022'!A14 -> Gideon Mwangi Kabaru | M2: ► | T2: ◄ | X2: ► | AB2: ◄ | AH2: ► | AL2: ◄ | AM2: =HYPERLINK("https://www.vertex42.com/ExcelTemplates/payslip-template.html","Payslip Template") -> Payslip Template
AM3: © 2019 Vertex42 LLC
A4: PAY PERIOD | E4: STANDARD HOURLY PAY | H4: OVERTIME HOURLY PAY | K4: HOLIDAY HOURLY PAY | N4: VACATION HOURLY PAY | Q4: OTHER HOURLY PAY | T4: OTHER EARNINGS | AB4: DEDUCTIONS
A5: PAY DATE | B5: FROM | C5: TO | D5: PERIOD | E5: Standard Hours | F5: Standard Pay Rate | G5: Basic Pay | H5: Overtime Hours | I5: Overtime Pay Rate | J5: Overtime Pay | K5: Holiday Hours | L5: Holiday Pay Rate | M5: Holiday Pay | N5: Vacation Hours | O5: Vacation Pay Rate | P5: Vacation Pay | Q5: Other Hours | R5: Other Pay Rate | S5: Other Hourly Pay | T5: Other Earning: Basic Pay | U5: Commission and Bonus | V5: Sick Pay | W5: Expenses | AB5: PAYE Tax | AC5: N.H.I.F | AD5: HELB | AE5: Pension | AF5: Union Fees | AG5: Non taxable reimbursements | AH5: TRF Bank | AM5: ← Customize these labels
A6: 44530 | D6: 44501 | E6: 160 | F6: 937.5 | G6: =E6*F6 -> 150000 | H6: 74.618432 | I6: =F6 -> 937.5 | J6: =H6*I6 -> 69954.78 | K6: 0 | L6: 0 | M6: =K6*L6 -> 0 | P6: =N6*O6 -> 0 | S6: =Q6*R6 -> 0 | T6: 0 | U6: 0 | V6: 0 | W6: 0 | AB6: 61054.78 | AC6: 1700 | AD6: 0 | AE6: 200 | AF6: 0 | AG6: 0 | AH6: =G6+J6+M6+T6+U6+V6+W6+AG6-AB6-AC6-AD6-AE6-AF6 -> 157000
A7: 44561 | D7: 44531 | E7: 160 | F7: 937.5 | G7: =E7*F7 -> 150000 | H7: 84.5232 | I7: =F7 -> 937.5 | J7: =H7*I7 -> 79240.5 | K7: 0 | L7: 0 | M7: =K7*L7 -> 0 | P7: =N7*O7 -> 0 | S7: =Q7*R7 -> 0 | T7: 0 | U7: 0 | V7: 0 | W7: 0 | AB7: 60840.5 | AC7: 1700 | AD7: 0 | AE7: 200 | AF7: 0 | AG7: 53420 | AH7: =G7+J7+M7+T7+U7+V7+W7+AG7-AB7-AC7-AD7-AE7-AF7 -> 219920
A8: 44592 | D8: 44562 | E8: 160 | F8: 937.5 | G8: =E8*F8 -> 150000 | H8: 74.335008 | I8: =F8 -> 937.5 | J8: =H8*I8 -> 69689.07 | K8: 0 | L8: 0 | M8: =K8*L8 -> 0 | P8: =N8*O8 -> 0 | S8: =Q8*R8 -> 0 | T8: 0 | U8: 0 | V8: 0 | W8: 0 | AB8: 57975.07 | AC8: 1700 | AD8: 0 | AE8: 200 | AF8: 0 | AG8: 0 | AH8: =G8+J8+M8+T8+U8+V8+W8+AG8-AB8-AC8-AD8-AE8-AF8 -> 159814 | AL8: =G8+J8-AB8-AC8-AE8 -> 159814
A9: 44620 | D9: 44593 | E9: 160 | F9: 937.5 | G9: =E9*F9 -> 150000 | H9: 74.335008 | I9: =F9 -> 937.5 | J9: =H9*I9 -> 69689.07 | K9: 0 | L9: 0 | M9: =K9*L9 -> 0 | P9: =N9*O9 -> 0 | S9: =Q9*R9 -> 0 | T9: 0 | U9: 0 | V9: 0 | W9: 0 | AB9: 57975.07 | AC9: 1700 | AD9: 0 | AE9: 200 | AF9: 0 | AG9: 67000 | AH9: =G9+J9+M9+T9+U9+V9+W9+AG9-AB9-AC9-AD9-AE9-AF9 -> 226814 | AL9: =G9+J9-AB9-AC9-AE9 -> 159814
A10: 44651 | D10: 44621 | E10: 160 | F10: 937.5 | G10: =E10*F10 -> 150000 | H10: 74.335008 | I10: =F10 -> 937.5 | J10: =H10*I10 -> 69689.07 | K10: 0 | L10: 0 | M10: =K10*L10 -> 0 | P10: =N10*O10 -> 0 | S10: =Q10*R10 -> 0 | T10: 0 | U10: 0 | V10: 0 | W10: 0 | AB10: 57975.07 | AC10: 1700 | AD10: 0 | AE10: 200 | AF10: 0 | AG10: 67000 | AH10: =G10+J10+M10+T10+U10+V10+W10+AG10-AB10-AC10-AD10-AE10-AF10 -> 226814 | AL10: =G10+J10-AB10-AC10-AE10 -> 159814 | AM10: More Templates
A11: =TODAY() -> 44930 | D11: 44652 | E11: 160 | F11: 937.5 | G11: =E11*F11 -> 150000 | H11: 74.335008 | I11: =F11 -> 937.5 | J11: =H11*I11 -> 69689.07 | K11: 0 | L11: 0 | M11: =K11*L11 -> 0 | P11: =N11*O11 -> 0 | S11: =Q11*R11 -> 0 | T11: 0 | U11: 0 | V11: 0 | W11: 0 | AB11: 57975.07 | AC11: 1700 | AD11: 0 | AE11: 200 | AF11: 0 | AG11: 0 | AH11: =G11+J11+M11+T11+U11+V11+W11+AG11-AB11-AC11-AD11-AE11-AF11 -> 159814 | AM11: =HYPERLINK("https://www.vertex42.com/ExcelTemplates/timesheets.html","► Timesheet Templates") -> ► Timesheet Templates
G12: =E12*F12 -> 0 | J12: =H12*I12 -> 0 | M12: =K12*L12 -> 0 | P12: =N12*O12 -> 0 | S12: =Q12*R12 -> 0 | AM12: =HYPERLINK("https://www.vertex42.com/ExcelTemplates/business-templates.html","► Business Templates") -> ► Business Templates
G13: =E13*F13 -> 0 | J13: =H13*I13 -> 0 | M13: =K13*L13 -> 0 | P13: =N13*O13 -> 0 | S13: =Q13*R13 -> 0 | AM13: =HYPERLINK("https://www.vertex42.com/ExcelTemplates/invoice-templates.html","► Invoice Templates") -> ► Invoice Templates
G14: =E14*F14 -> 0 | J14: =H14*I14 -> 0 | M14: =K14*L14 -> 0 | P14: =N14*O14 -> 0 | S14: =Q14*R14 -> 0
G15: =E15*F15 -> 0 | J15: =H15*I15 -> 0 | M15: =K15*L15 -> 0 | P15: =N15*O15 -> 0 | S15: =Q15*R15 -> 0
G16: =E16*F16 -> 0 | J16: =H16*I16 -> 0 | M16: =K16*L16 -> 0 | P16: =N16*O16 -> 0 | S16: =Q16*R16 -> 0
G17: =E17*F17 -> 0 | J17: =H17*I17 -> 0 | M17: =K17*L17 -> 0 | P17: =N17*O17 -> 0 | S17: =Q17*R17 -> 0
G18: =E18*F18 -> 0 | J18: =H18*I18 -> 0 | M18: =K18*L18 -> 0 | P18: =N18*O18 -> 0 | S18: =Q18*R18 -> 0
G19: =E19*F19 -> 0 | J19: =H19*I19 -> 0 | M19: =K19*L19 -> 0 | P19: =N19*O19 -> 0 | S19: =Q19*R19 -> 0
G20: =E20*F20 -> 0 | J20: =H20*I20 -> 0 | M20: =K20*L20 -> 0 | P20: =N20*O20 -> 0 | S20: =Q20*R20 -> 0
G21: =E21*F21 -> 0 | J21: =H21*I21 -> 0 | M21: =K21*L21 -> 0 | P21: =N21*O21 -> 0 | S21: =Q21*R21 -> 0
G22: =E22*F22 -> 0 | J22: =H22*I22 -> 0 | M22: =K22*L22 -> 0 | P22: =N22*O22 -> 0 | S22: =Q22*R22 -> 0
G23: =E23*F23 -> 0 | J23: =H23*I23 -> 0 | M23: =K23*L23 -> 0 | P23: =N23*O23 -> 0 | S23: =Q23*R23 -> 0
G24: =E24*F24 -> 0 | J24: =H24*I24 -> 0 | M24: =K24*L24 -> 0 | P24: =N24*O24 -> 0 | S24: =Q24*R24 -> 0
G25: =E25*F25 -> 0 | J25: =H25*I25 -> 0 | M25: =K25*L25 -> 0 | P25: =N25*O25 -> 0 | S25: =Q25*R25 -> 0
... G31: =E31*F31 -> 0 | J31: =H31*I31 -> 0 | M31: =K31*L31 -> 0 | P31: =N31*O31 -> 0 | S31: =Q31*R31 -> 0
G32: =E32*F32 -> 0 | J32: =H32*I32 -> 0 | M32: =K32*L32 -> 0 | P32: =N32*O32 -> 0 | S32: =Q32*R32 -> 0 | AM32: ← Insert new rows above this one
A33: Year-To-Date | E33: =SUM(E5:E32) -> 960 | G33: =SUM(G5:G32) -> 900000 | H33: =SUM(H5:H32) -> 456.48166 | I33: =SUM(I5:I32) -> 5625 | J33: =SUM(J5:J32) -> 427951.56 | K33: =SUM(K5:K32) -> 0 | L33: =SUM(L5:L32) -> 0 | M33: =SUM(M5:M32) -> 0 | N33: =SUM(N5:N32) -> 0 | ... AK33: =SUM(AK5:AK32) -> 0
